<mujoco model="right_hand_mvp4">
  <compiler angle="radian"/>
  <!-- <option collision="all"/> -->

  <default>
      <!-- use same geom params as the Shadow Hand model in IsaacGymEnv for now -->
      <!-- the density is adjusted so that the total weight of the hand part (not including the base) is the same as the real hand (106g) (therefore the base will have a wrong mass, which shouldn't matter for now) -->
      <geom rgba="1 1 1 1" type="mesh" density="662" friction="1 0.005 0.001" condim="3" margin="0.0005" contype="1" conaffinity="1"/>
      <!-- use same joint params as IsaacGymEnv for now -->
      <!-- TODO: joint damping and position control kp should eventually be set to sysID'ed values -->
      <joint type="hinge" limited="true" damping="0.05" armature="0.001" margin="0.01" frictionloss="0.001"/>
      <!-- actuator configuration -->
      <position ctrllimited="true" forcelimited="true" forcerange="-1 1" kp="2."/>
      <!-- the tendon which limits the two joints creating the rolling joint should be very limited in its length range -->
      <tendon limited="true" range="-0.001 0.001"/>
  </default>

  <asset>
    <texture type="2d" name="checkerboard" builtin="checker" rgb1="0 0 0.2" rgb2="0.1 0.1 0.6" width="512" height="512"/>
    <material name="checkerboard_mat" texture="checkerboard" texuniform="true" texrepeat="10 10"/>
    <mesh name="tip_motion_sensor" file="mesh_2/tip_motion_sensor.stl"/>
    <mesh name="f_medial_silicone" file="mesh_2/f_medial_silicone.stl"/>
    <mesh name="f_proximal_silicone" file="mesh_2/f_proximal_silicone.stl"/>
    <mesh name="silicone_thumb" file="mesh_2/silicone_thumb.stl"/>
    <mesh name="palm_pad" file="mesh_2/palm_pad.stl"/>
    <mesh name="palm_pad2" file="mesh_2/palm_pad2.stl"/>
    <mesh name="palm" file="mesh_2/Palm.stl"/>
    <mesh name="split_palm" file="mesh_2/split_palm2.stl"/>
    <mesh name="motorblock" file="mesh_2/motorblock.stl"/>
    <mesh name="wrist_mount" file="mesh_2/wrist_mount.stl"/>
    <mesh name="f1_long" file="mesh_2/f_long.stl"/>
    <mesh name="f1_short" file="mesh_2/f_short.stl"/>
    <mesh name="mounting_feature" file="mesh_2/mounting_feature.stl"/>
    <mesh name="metacarpal" file="mesh_2/metacarpal.stl"/>
    <mesh name="thumb_abduction" file="mesh_2/thumb_abduction.stl"/>
    <mesh name="f2_base" file="mesh_2/f_base.stl"/>
    <mesh name="f2_abad" file="mesh_2/f_abad.stl"/>
    <mesh name="f2_long" file="mesh_2/f_long.stl"/>
    <mesh name="f2_short" file="mesh_2/f_short.stl"/>
    <mesh name="f2_tip" file="mesh_2/f_sensortip.stl"/>
    <mesh name="f3_base" file="mesh_2/f_base.stl"/>
    <mesh name="f3_abad" file="mesh_2/f_abad.stl"/>
    <mesh name="f3_long" file="mesh_2/f_long.stl"/>
    <mesh name="f3_short" file="mesh_2/f_short.stl"/>
    <mesh name="f3_tip" file="mesh_2/f_sensortip.stl"/>
    <mesh name="f4_base" file="mesh_2/f_no_abad_base.stl"/>
    <mesh name="f4_long" file="mesh_2/f_long.stl"/>
    <mesh name="f4_short" file="mesh_2/f_short.stl"/>
    <mesh name="f4_tip" file="mesh_2/f_sensortip.stl"/>
    <mesh name="f5_base" file="mesh_2/f_no_abad_base.stl"/>
    <mesh name="f5_long" file="mesh_2/f_long.stl"/>
    <mesh name="f5_short" file="mesh_2/f_short.stl"/>
    <mesh name="f5_tip" file="mesh_2/f_sensortip.stl"/>
  </asset>

  <worldbody>
    <geom name="ground" size="10 10 0.1" pos="0 0 -1" type="plane" material="checkerboard_mat" rgba="0.8 0.8 0.8 1"/>
    <camera name="fixed_cam" pos="0 0 1"/>
    <body name="root" quat="0.5 0.5 0.5 0.5">
      <geom mesh="motorblock"/>
      <geom pos="0.155 -0.011 0" quat="0 0.707107 0 0.707107" mesh="wrist_mount"/>
      <body name="palm" pos="0.1485 -0.011 0" quat="-0.5 0.5 0.5 0.5">
        <geom mesh="palm"/>
        <geom rgba="0.1 0.1 0.1 1" mesh="palm_pad"/>
        <geom pos="0.05874 0.06624 0" quat="0.961212 0 0 -0.27581" mesh="mounting_feature"/>
        <site name="goal_site" pos="0.00699 0.07109 0.008" size="0.002" rgba="1 0 0 1"/>
        <body name="metacarpal" pos="0.02323 0.00942 0" quat="0.993562 0 0 0.113294">
          <joint name="metacarpal_joint" pos="0 0 0" axis="-0.707107 -0.707107 0" range="-1.5 1.5"/>
          <geom mesh="metacarpal"/>
          <body name="thumb_abduction" pos="0.03349 0.013 0" quat="-0.0987034 0.369735 0.89262 -0.238291">
            <joint name="thumb_abduction_joint" pos="0 0 0" axis="0 0 1" range="-1.5 1.5"/>
            <geom mesh="thumb_abduction"/>
            <body name="f1_base_virtual" pos="-0.02213 0 0.0025">
              <inertial pos="0 0 0" mass="0.001" diaginertia="4e-10 4e-10 3e-10"/>
              <joint name="f1_base_long_joint_virt" pos="0 0 0" axis="0 -1 0" range="-0.1 0.8"/>
              <body name="f1_long" pos="-0.009 0.001 0" quat="0 0 1 0">
                <joint name="f1_base_long_joint" pos="0.009 0 0" axis="0 -1 0" range="-0.1 1"/>
                <geom mesh="f1_long"/>
                <geom rgba="0.1 0.1 0.1 1" mesh="f_proximal_silicone"/>
                <body name="f1_long_short_joint_virt" pos="0.03508 0 -0.001">
                  <inertial pos="0 0 0" mass="0.001" diaginertia="4e-10 4e-10 3e-10"/>
                  <joint name="f1_long_short_joint_virt" pos="0 0 0" axis="0 -1 0" range="-0.1 0.8"/>
                  <body name="f1_short" pos="0.006 0 0">
                    <joint name="f1_long_short_joint" pos="0.006 0 0" axis="0 -1 0" range="-0.1 0.8"/>
                    <geom mesh="f1_short"/>
                    <geom rgba="0.1 0.1 0.1 1" mesh="silicone_thumb"/>
                  </body>
                </body>
              </body>
            </body>
          </body>
        </body>
        <body name="f2_base" pos="0.04139 0.08849 0.00247" quat="0.761631 -0.639548 0.0671287 -0.0799429">
          <!-- <geom contype="0" conaffinity="0" mesh="f2_base"/> -->
          <geom mesh="f2_base"/>
          <body name="f2_base_virtual" pos="0 0 -0.00022495">
            <inertial pos="0 0 0" mass="0.001" diaginertia="4e-10 4e-10 3e-10"/>
            <joint name="f2_base_abad_joint_virt" pos="0 0 0" axis="0 1 0" range="-0.2 0.2"/>
            <body name="f2_abad" pos="0 0.0025 0.011785" quat="0.707107 0 0 0.707107">
              <joint name="f2_base_abad_joint" pos="0 0 0.00622" axis="1 0 0" range="-0.2 0.2"/>
              <geom mesh="f2_abad"/>
              <body name="f2_abad_long_joint_virt">
                <inertial pos="0 0 0" mass="0.001" diaginertia="4e-10 4e-10 3e-10"/>
                <joint name="f2_abad_long_joint_virt" pos="0 0 0" axis="0 -1 0" range="-0.1 0.8"/>
                <body name="f2_long" pos="0 0 0.009" quat="0.707107 0 -0.707107 0">
                  <joint name="f2_abad_long_joint" pos="0.009 0 0" axis="0 -1 0" range="-0.1 0.8"/>
                  <geom mesh="f2_long"/>
                  <geom rgba="0.1 0.1 0.1 1" mesh="f_proximal_silicone"/>
                  <body name="f2_long_short_joint_virt" pos="0.03508 0 -0.001">
                    <inertial pos="0 0 0" mass="0.001" diaginertia="4e-10 4e-10 3e-10"/>
                    <joint name="f2_long_short_joint_virt" pos="0 0 0" axis="0 -1 0" range="-0.1 0.8"/>
                    <body name="f2_short" pos="0.006 0 0">
                      <joint name="f2_long_short_joint" pos="0.006 0 0" axis="0 -1 0" range="-0.1 0.8"/>
                      <geom mesh="f2_short"/>
                      <geom rgba="0.1 0.1 0.1 1" mesh="f_medial_silicone"/>
                      <body name="f2_short_tip_joint_virt" pos="0.023 0 0">
                        <inertial pos="0 0 0" mass="0.001" diaginertia="4e-10 4e-10 3e-10"/>
                        <joint name="f2_short_tip_joint_virt" pos="0 0 0" axis="0 -1 0" range="-0.1 0.8"/>
                        <body name="f2_tip" pos="0.0045 0 0">
                          <joint name="f2_short_tip_joint" pos="0.0045 0 0" axis="0 -1 0" range="-0.1 0.8"/>
                          <geom mesh="f2_tip"/>
                          <geom rgba="0.1 0.1 0.1 1" mesh="tip_motion_sensor"/>
                        </body>
                      </body>
                    </body>
                  </body>
                </body>
              </body>
            </body>
          </body>
        </body>
        <body name="f3_base" pos="0.01774 0.09097 0.00247" quat="0.766118 -0.6427 0 0">
          <geom mesh="f3_base"/>
          <body name="f3_base_virtual" pos="0 0 -0.00022495">
            <inertial pos="0 0 0" mass="0.001" diaginertia="4e-10 4e-10 3e-10"/>
            <joint name="f3_base_abad_joint_virt" pos="0 0 0" axis="0 1 0" range="-0.2 0.2"/>
            <body name="f3_abad" pos="0 0.0025 0.011785" quat="0.707107 0 0 0.707107">
              <joint name="f3_base_abad_joint" pos="0 0 0.00622" axis="1 0 0" range="-0.2 0.2"/>
              <geom mesh="f3_abad"/>
              <body name="f3_abad_long_joint_virt">
                <inertial pos="0 0 0" mass="0.001" diaginertia="4e-10 4e-10 3e-10"/>
                <joint name="f3_abad_long_joint_virt" pos="0 0 0" axis="0 -1 0" range="-0.1 0.8"/>
                <body name="f3_long" pos="0 0 0.009" quat="0.707107 0 -0.707107 0">
                  <joint name="f3_abad_long_joint" pos="0.009 0 0" axis="0 -1 0" range="-0.1 0.8"/>
                  <geom mesh="f3_long"/>
                  <geom rgba="0.1 0.1 0.1 1" mesh="f_proximal_silicone"/>
                  <body name="f3_long_short_joint_virt" pos="0.03508 0 -0.001">
                    <inertial pos="0 0 0" mass="0.001" diaginertia="4e-10 4e-10 3e-10"/>
                    <joint name="f3_long_short_joint_virt" pos="0 0 0" axis="0 -1 0" range="-0.1 0.8"/>
                    <body name="f3_short" pos="0.006 0 0">
                      <joint name="f3_long_short_joint" pos="0.006 0 0" axis="0 -1 0" range="-0.1 0.8"/>
                      <geom mesh="f3_short"/>
                      <geom rgba="0.1 0.1 0.1 1" mesh="f_medial_silicone"/>
                      <body name="f3_short_tip_joint_virt" pos="0.023 0 0">
                        <inertial pos="0 0 0" mass="0.001" diaginertia="4e-10 4e-10 3e-10"/>
                        <joint name="f3_short_tip_joint_virt" pos="0 0 0" axis="0 -1 0" range="-0.1 0.8"/>
                        <body name="f3_tip" pos="0.0045 0 0">
                          <joint name="f3_short_tip_joint" pos="0.0045 0 0" axis="0 -1 0" range="-0.1 0.8"/>
                          <geom mesh="f3_tip"/>
                          <geom rgba="0.1 0.1 0.1 1" mesh="tip_motion_sensor"/>
                        </body>
                      </body>
                    </body>
                  </body>
                </body>
              </body>
            </body>
          </body>
        </body>
        <body name="split_palm" pos="-0.01041 0.05839 0.008">
          <geom mesh="split_palm"/>
          <geom rgba="0.1 0.1 0.1 1" mesh="palm_pad2"/>
          <body name="f4_base" pos="0.00346 0.03441 -0.00685" quat="0.502602 -0.484853 0.421757 0.578299">
            <geom mesh="f4_base"/>
            <body name="f4_base_virtual">
              <inertial pos="0 0 0" mass="0.001" diaginertia="4e-10 4e-10 3e-10"/>
              <joint name="f4_base_long_joint_virt" pos="0 0 0" axis="0 -1 0" range="-0.1 0.8"/>
              <body name="f4_long" pos="0 0 0.009" quat="0.707107 0 -0.707107 0">
                <joint name="f4_base_long_joint" pos="0.009 0 0" axis="0 -1 0" range="-0.1 0.8"/>
                <geom mesh="f4_long"/>
                <geom rgba="0.1 0.1 0.1 1" mesh="f_proximal_silicone"/>
                <body name="f4_long_short_joint_virt" pos="0.03508 0 -0.001">
                  <inertial pos="0 0 0" mass="0.001" diaginertia="4e-10 4e-10 3e-10"/>
                  <joint name="f4_long_short_joint_virt" pos="0 0 0" axis="0 -1 0" range="-0.1 0.8"/>
                  <body name="f4_short" pos="0.006 0 0">
                    <joint name="f4_long_short_joint" pos="0.006 0 0" axis="0 -1 0" range="-0.1 0.8"/>
                    <geom mesh="f4_short"/>
                    <geom rgba="0.1 0.1 0.1 1" mesh="f_medial_silicone"/>
                    <body name="f4_short_tip_joint_virt" pos="0.023 0 0">
                      <inertial pos="0 0 0" mass="0.001" diaginertia="4e-10 4e-10 3e-10"/>
                      <joint name="f4_short_tip_joint_virt" pos="0 0 0" axis="0 -1 0" range="-0.1 0.8"/>
                      <body name="f4_tip" pos="0.0045 0 0">
                        <joint name="f4_short_tip_joint" pos="0.0045 0 0" axis="0 -1 0" range="-0.1 0.8"/>
                        <geom mesh="f4_tip"/>
                        <geom rgba="0.1 0.1 0.1 1" mesh="tip_motion_sensor"/>
                      </body>
                    </body>
                  </body>
                </body>
              </body>
            </body>
          </body>
          <body name="f5_base" pos="-0.02 0.02985 -0.00685" quat="0.471961 -0.506441 0.395454 0.603645">
            <geom mesh="f5_base"/>
            <body name="f5_base_virtual">
              <inertial pos="0 0 0" mass="0.001" diaginertia="4e-10 4e-10 3e-10"/>
              <joint name="f5_base_long_joint_virt" pos="0 0 0" axis="0 -1 0" range="-0.1 0.8"/>
              <body name="f5_long" pos="0 0 0.009" quat="0.707107 0 -0.707107 0">
                <joint name="f5_base_long_joint" pos="0.009 0 0" axis="0 -1 0" range="-0.1 0.8"/>
                <geom mesh="f5_long"/>
                <geom rgba="0.1 0.1 0.1 1" mesh="f_proximal_silicone"/>
                <body name="f5_long_short_joint_virt" pos="0.03508 0 -0.001">
                  <inertial pos="0 0 0" mass="0.001" diaginertia="4e-10 4e-10 3e-10"/>
                  <joint name="f5_long_short_joint_virt" pos="0 0 0" axis="0 -1 0" range="-0.1 0.8"/>
                  <body name="f5_short" pos="0.006 0 0">
                    <joint name="f5_long_short_joint" pos="0.006 0 0" axis="0 -1 0" range="-0.1 0.8"/>
                    <geom mesh="f5_short"/>
                    <geom rgba="0.1 0.1 0.1 1" mesh="f_medial_silicone"/>
                    <body name="f5_short_tip_joint_virt" pos="0.023 0 0">
                      <inertial pos="0 0 0" mass="0.001" diaginertia="4e-10 4e-10 3e-10"/>
                      <joint name="f5_short_tip_joint_virt" pos="0 0 0" axis="0 -1 0" range="-0.1 0.8"/>
                      <body name="f5_tip" pos="0.0045 0 0">
                        <joint name="f5_short_tip_joint" pos="0.0045 0 0" axis="0 -1 0" range="-0.1 0.8"/>
                        <geom mesh="f5_tip"/>
                        <geom rgba="0.1 0.1 0.1 1" mesh="tip_motion_sensor"/>
                      </body>
                    </body>
                  </body>
                </body>
              </body>
            </body>
          </body>
        </body>
      </body>
    </body>
  </worldbody>

  <contact>
    <exclude body1="root" body2="palm"/>
    <exclude body1="palm" body2="split_palm"/>
    <exclude body1="thumb_abduction" body2="f1_long"/>
    <exclude body1="f1_long" body2="f1_short"/>
    <exclude body1="f2_base" body2="f2_abad"/>
    <exclude body1="f2_abad" body2="f2_long"/>
    <exclude body1="f2_long" body2="f2_short"/>
    <exclude body1="f2_short" body2="f2_tip"/>
    <exclude body1="f3_base" body2="f3_abad"/>
    <exclude body1="f3_abad" body2="f3_long"/>
    <exclude body1="f3_long" body2="f3_short"/>
    <exclude body1="f3_short" body2="f3_tip"/>
    <exclude body1="f4_base" body2="f4_long"/>
    <exclude body1="f4_long" body2="f4_short"/>
    <exclude body1="f4_short" body2="f4_tip"/>
    <exclude body1="f5_base" body2="f5_long"/>
    <exclude body1="f5_long" body2="f5_short"/>
    <exclude body1="f5_short" body2="f5_tip"/>
  </contact>

  <tendon>
    <fixed name="f1_base_long_joint">
      <joint joint="f1_base_long_joint_virt" coef="1"/>
      <joint joint="f1_base_long_joint" coef="-1"/>
    </fixed>
    <fixed name="f1_long_short_joint">
      <joint joint="f1_long_short_joint_virt" coef="1"/>
      <joint joint="f1_long_short_joint" coef="-1"/>
    </fixed>
    <fixed name="f2_base_abad_joint">
      <joint joint="f2_base_abad_joint_virt" coef="1"/>
      <joint joint="f2_base_abad_joint" coef="-1"/>
    </fixed>
    <fixed name="f2_abad_long_joint">
      <joint joint="f2_abad_long_joint_virt" coef="1"/>
      <joint joint="f2_abad_long_joint" coef="-1"/>
    </fixed>
    <fixed name="f2_long_short_joint">
      <joint joint="f2_long_short_joint_virt" coef="1"/>
      <joint joint="f2_long_short_joint" coef="-1"/>
    </fixed>
    <fixed name="f2_index_join_link">
      <joint joint="f2_long_short_joint" coef="0.71"/>
      <joint joint="f2_short_tip_joint_virt" coef="-1"/>
    </fixed>
    <fixed name="f2_short_tip_joint">
      <joint joint="f2_short_tip_joint_virt" coef="1"/>
      <joint joint="f2_short_tip_joint" coef="-1"/>
    </fixed>
    <fixed name="f3_base_abad_joint">
      <joint joint="f3_base_abad_joint_virt" coef="1"/>
      <joint joint="f3_base_abad_joint" coef="-1"/>
    </fixed>
    <fixed name="f3_abad_long_joint">
      <joint joint="f3_abad_long_joint_virt" coef="1"/>
      <joint joint="f3_abad_long_joint" coef="-1"/>
    </fixed>
    <fixed name="f3_long_short_joint">
      <joint joint="f3_long_short_joint_virt" coef="1"/>
      <joint joint="f3_long_short_joint" coef="-1"/>
    </fixed>
    <fixed name="f3_index_join_link">
      <joint joint="f3_long_short_joint" coef="0.71"/>
      <joint joint="f3_short_tip_joint_virt" coef="-1"/>
    </fixed>
    <fixed name="f3_short_tip_joint">
      <joint joint="f3_short_tip_joint_virt" coef="1"/>
      <joint joint="f3_short_tip_joint" coef="-1"/>
    </fixed>
    <fixed name="f4_base_long_joint">
      <joint joint="f4_base_long_joint_virt" coef="1"/>
      <joint joint="f4_base_long_joint" coef="-1"/>
    </fixed>
    <fixed name="f4_long_short_joint">
      <joint joint="f4_long_short_joint_virt" coef="1"/>
      <joint joint="f4_long_short_joint" coef="-1"/>
    </fixed>
    <fixed name="f4_index_join_link">
      <joint joint="f4_long_short_joint" coef="0.71"/>
      <joint joint="f4_short_tip_joint_virt" coef="-1"/>
    </fixed>
    <fixed name="f4_short_tip_joint">
      <joint joint="f4_short_tip_joint_virt" coef="1"/>
      <joint joint="f4_short_tip_joint" coef="-1"/>
    </fixed>
    <fixed name="f5_base_long_joint">
      <joint joint="f5_base_long_joint_virt" coef="1"/>
      <joint joint="f5_base_long_joint" coef="-1"/>
    </fixed>
    <fixed name="f5_long_short_joint">
      <joint joint="f5_long_short_joint_virt" coef="1"/>
      <joint joint="f5_long_short_joint" coef="-1"/>
    </fixed>
    <fixed name="f5_index_join_link">
      <joint joint="f5_long_short_joint" coef="0.71"/>
      <joint joint="f5_short_tip_joint_virt" coef="-1"/>
    </fixed>
    <fixed name="f5_short_tip_joint">
      <joint joint="f5_short_tip_joint_virt" coef="1"/>
      <joint joint="f5_short_tip_joint" coef="-1"/>
    </fixed>
  </tendon>

  <actuator>
      <!-- <position name="wrist_joint" joint="wrist_joint" ctrlrange="-0.5 0.5"/> -->
      <!-- <position name="split_palm_joint" joint="split_palm_joint" ctrlrange="0 1"/> -->
      <position name="metacarpal_joint" joint="metacarpal_joint" ctrlrange="-1.5 1.5"/> 
      <position name="thumb_abduction_joint" joint="thumb_abduction_joint" ctrlrange="-1.5 1.5"/> 
      <position name="f1_base_long_joint" joint="f1_base_long_joint" ctrlrange="-0.1 0.8"/>
      <position name="f1_long_short_joint" joint="f1_long_short_joint" ctrlrange="-0.1 0.8" kp="4"/>
      <position name="f2_base_abad_joint" joint="f2_base_abad_joint" ctrlrange="-0.2 0.2"/>
      <position name="f2_abad_long_joint" joint="f2_abad_long_joint" ctrlrange="-0.1 0.8"/>
      <position name="f2_long_short_joint" joint="f2_long_short_joint" ctrlrange="-0.1 0.8" kp="4"/>
      <position name="f3_base_abad_joint" joint="f3_base_abad_joint" ctrlrange="-0.2 0.2"/>
      <position name="f3_abad_long_joint" joint="f3_abad_long_joint" ctrlrange="-0.1 0.8"/>
      <position name="f3_long_short_joint" joint="f3_long_short_joint" ctrlrange="-0.1 0.8" kp="4"/>
      <position name="f4_base_long_joint" joint="f4_base_long_joint" ctrlrange="-0.1 0.8"/>
      <position name="f4_long_short_joint" joint="f4_long_short_joint" ctrlrange="-0.1 0.8" kp="4"/>
      <position name="f5_base_long_joint" joint="f5_base_long_joint" ctrlrange="-0.1 0.8"/>
      <position name="f5_long_short_joint" joint="f5_long_short_joint" ctrlrange="-0.1 0.8" kp="4"/>
  </actuator>

  <sensor>
    <jointpos joint="metacarpal_joint" name="metacarpal_joint"/>
    <jointpos joint="thumb_abduction_joint" name="thumb_abduction_joint"/>
    <jointpos joint="f1_base_long_joint" name="f1_base_long_joint"/>
    <jointpos joint="f1_long_short_joint" name="f1_long_short_joint"/>
    <jointpos joint="f2_base_abad_joint" name="f2_base_abad_joint"/>
    <jointpos joint="f2_abad_long_joint" name="f2_abad_long_joint"/>
    <jointpos joint="f2_long_short_joint" name="f2_long_short_joint"/>
    <jointpos joint="f2_short_tip_joint" name="f2_short_tip_joint"/>
    <jointpos joint="f3_base_abad_joint" name="f3_base_abad_joint"/>
    <jointpos joint="f3_abad_long_joint" name="f3_abad_long_joint"/>
    <jointpos joint="f3_long_short_joint" name="f3_long_short_joint"/>
    <jointpos joint="f3_short_tip_joint" name="f3_short_tip_joint"/>
    <jointpos joint="f4_base_long_joint" name="f4_base_long_joint"/>
    <jointpos joint="f4_long_short_joint" name="f4_long_short_joint"/>
    <jointpos joint="f4_short_tip_joint" name="f4_short_tip_joint"/>
    <jointpos joint="f5_base_long_joint" name="f5_base_long_joint"/>
    <jointpos joint="f5_long_short_joint" name="f5_long_short_joint"/>
    <jointpos joint="f5_short_tip_joint" name="f5_short_tip_joint"/>
  </sensor>
</mujoco>
